#VRML_SIM R2021a utf8
WorldInfo {
  coordinateSystem "NUE"
  contactProperties [
    ContactProperties {
      material1 "passive_wheel"
      coulombFriction [
        0
      ]
    }
  ]
}
Viewpoint {
  orientation -0.07176105013372504 -0.9941322725067713 -0.08094057353532652 2.265299028830237
  position -9.055895968135548 3.066457076818157 -6.604413944781184
}
TexturedBackground {
}
TexturedBackgroundLight {
}
DEF GROUND Solid {
  children [
    DEF GROUND_SHAPE Group {
      children [
        Transform {
          translation -8 0 -8
          children [
            Shape {
              appearance Grass {
                type "mossy"
                textureTransform TextureTransform {
                  scale 8.5 8.5
                }
              }
              geometry ElevationGrid {
                height [
                  0, 0, 0, 0, 0, 0, 0, 0, 0, 0, 0, 0, 0, 0, 0, 0, 0, 0, 0.0734148, 0.277421, 0.254337, 0.270417, 0.174982, 0.171189, 0.2473, 0.240992, 0.152361, 0.110575, 0.0978332, 0.126226, 0.106899, 0.0670659, 0.00953075, 0, 0, 0.499106, 0.798685, 0.613379, 0.322475, 0.287311, 0.266366, 0.418124, 0.525612, 0.451978, 0.30729, 0.0753625, 0.0480358, 0.0532171, 0.0870809, 0.0265759, 0, 0, 0.862448, 1.07618, 0.821001, 0.384595, 0.210389, 0.0983306, 0.331182, 0.347343, 0.263181, 0.13356, 0.0145599, 0.0762221, 0.100532, 0.243507, 0.159553, 0, 0, 0.75534, 0.984221, 0.864925, 0.447235, 0.0751634, 0.0222157, 0.078995, 0.102868, 0.0300013, 0.0114454, 0.00744961, 0.00984787, 0.204083, 0.520919, 0.461261, 0, 0, 0.362822, 0.603904, 0.566029, 0.340368, 0.102151, 0.0404528, 0.0668038, 0.00744951, 0.00933689, 0.0504858, 0.00744961, -0.000948593, 0.113054, 0.320988, 0.289012, 0, 0, 0.24704, 0.327251, 0.277966, 0.170757, 0.0771545, 0.0929641, 0.00744947, 0.00744951, 0.00744954, 0.00744958, 0.00744961, 0.0223858, 0.0165338, 0.0943175, 0.0460902, 0, 0, 0.205381, 0.266736, 0.119044, 0.124862, 0.0668763, 0.106241, 0.00744947, 0.00744951, 0.00744954, 0.00744958, 0.00744961, 0.00747269, 0.0113116, 0.0207513, 0.0670393, 0, 0, 0.131618, 0.109085, 0.0721561, 0.169558, 0.124192, 0.00986459, 0.00744947, 0.00744951, 0.00744954, 0.031045, 0.0443939, 0.00800915, 0.0184385, 0.0427789, 0.204962, 0, 0, 0.283209, 0.135281, 0.068453, 0.212608, 0.159615, 0.0361041, 0.00744947, 0.00744951, 0.0121282, 0.145762, 0.2493, 0.0458433, 0.0131252, 0.131277, 0.19891, 0, 0, 0.660028, 0.539195, 0.111397, 0.132591, 0.105425, 0.0289037, 0.00744947, 0.00744951, 0.00930376, 0.162809, 0.219176, 0.0290093, 0.0131459, 0.0436956, 0.0856175, 0, 0, 0.577927, 0.513154, 0.0907302, 0.0479889, 0.0704255, 0.019278, 0.00747491, 0.00932149, 0.0307641, 0.178685, 0.171126, 0.00346421, 0.0308989, 0.0948634, 0.262075, 0, 0, 0.315194, 0.205858, 0.0314991, 0.0365704, 0.127151, 0.142281, 0.00631048, 0.0559231, 0.196945, 0.333009, 0.17502, 0.00950381, 0.0639322, 0.243806, 0.282763, 0, 0, 0.233297, 0.177544, 0.0450179, 0.0682162, 0.129357, 0.0562887, 0.0190858, 0.120147, 0.389857, 0.381918, 0.0861915, -0.000387524, 0.178523, 0.482041, 0.357671, 0, 0, 0.00946765, 0.0925988, 0.208856, 0.242312, 0.359189, 0.320955, 0.189391, 0.194184, 0.352838, 0.288278, 0.142815, 0.143518, 0.27195, 0.517513, 0.504371, 0, 0, 0.037447, 0.126832, 0.314132, 0.26641, 0.227191, 0.16272, 0.107686, 0.12869, 0.0911368, 0.130659, 0.0368771, 0.108887, 0.0914181, 0.249301, 0.291638, 0, 0, 0, 0, 0, 0, 0, 0, 0, 0, 0, 0, 0, 0, 0, 0, 0, 0
                ]
                xDimension 17
                zDimension 17
              }
            }
          ]
        }
        Shape {
          appearance Grass {
            type "mossy"
            textureTransform TextureTransform {
              scale 250 250
            }
          }
          geometry Plane {
            size 500 500
          }
        }
      ]
    }
  ]
  boundingObject USE GROUND_SHAPE
}
Rock10cm {
  translation -1.02326 0 -0.866326
}
Oak {
}
Tree {
}
SimpleTree {
  name "tree(1)"
}
E-puck {
  hidden position_0_0 4.555180794726208
  hidden position_0_1 4.577466204002052
  hidden linearVelocity_0 3.4287745145405257e-07 -0.051852457602149106 -0.0001893435201855429
  hidden angularVelocity_0 0.011037914916979044 -1.5853418463561872e-06 1.7998133063064124e-05
  hidden rotation_1 -1 0 0 4.555180794726208
  hidden linearVelocity_1 3.458090569741537e-07 -0.04846021660334367 -0.00011107629483708673
  hidden angularVelocity_1 -0.03728173407762751 5.794382328554341e-06 -0.00016032355533690502
  hidden rotation_2 -1 0 0 4.577466204002052
  hidden linearVelocity_2 -6.965951556046009e-08 -0.048460356666528114 -0.00011088450371403705
  hidden angularVelocity_2 -0.03728320690809516 4.126765419980579e-06 1.3385882271868364e-05
  translation -3.342055979345598e-05 -0.019919037119322434 -0.01402946543671386
  rotation -0.999113630581381 0.04204316052430242 0.00207986528872634 -0.045115509572190106
}
Wheelbarrow {
}
Gnome {
}
Rock17cm {
  translation 1.7806 -0.037219 -0.212539
  rotation 0 -1 0 4.61434
  name "rock 17 cm(1)"
}
Rock17cm {
  translation 0.889895 0 0.814429
  name "rock 17 cm(2)"
}
Rock17cm {
  translation 2.36097 0 -2.2847
  rotation 0 -1 0 3.40996
  name "rock 17 cm(3)"
}
Rock17cm {
  translation 0.215003 0 -2.19116
}
Create {
  hidden position_0_1 1.0799049990803189e-07
  hidden position_0_2 1.0804790103336816e-07
  hidden linearVelocity_0 -2.0132371994234567e-12 -2.5848796787230592e-14 -1.415547660590331e-14
  hidden angularVelocity_0 -2.812329510158719e-13 -6.588901725353965e-13 7.597151389395743e-13
  hidden linearVelocity_1 -2.1899297507817103e-12 -3.318234575999667e-14 -8.644079796528106e-14
  hidden angularVelocity_1 -2.824831392346933e-13 -6.596664088089021e-13 7.599918726405304e-13
  hidden translation_8 0.135878 -0.014 0.006176
  hidden rotation_8 -0.9999999999999999 0 0 1.0745380149674385e-07
  hidden linearVelocity_8 -2.052817508715334e-12 8.549718564550534e-15 6.746107796306204e-14
  hidden angularVelocity_8 -1.0426680898054011e-13 -6.592151349765414e-13 7.923498026854536e-13
  hidden translation_9 -0.135878 -0.014 0.006176
  hidden rotation_9 -1 0 0 1.0745380149674385e-07
  hidden linearVelocity_9 -1.9634090570532017e-12 -9.520583605827405e-16 -8.744244613745333e-14
  hidden angularVelocity_9 -4.872939179209155e-14 -6.592199433094522e-13 9.924214936180954e-13
  hidden translation_13 -1.7208456881689926e-14 -3.1391931011245933e-06 6.581316602805032e-09
  hidden rotation_13 -1.0782448805050623e-16 1 5.649492356049151e-17 0.7269320000000001
  hidden linearVelocity_13 -1.929973425995836e-12 -7.620570841027074e-14 -2.7448733255562254e-14
  hidden angularVelocity_13 -2.815113712124314e-13 -6.595834956144318e-13 7.587315032140078e-13
  hidden translation_14 -1.7486012637846216e-14 -3.139193101152349e-06 6.581316602805032e-09
  hidden rotation_14 8.08161625025673e-18 1 -5.2149297312977397e-17 -0.7269299999999996
  hidden linearVelocity_14 -1.9917946101190953e-12 6.011191544530448e-14 6.756421652224916e-14
  hidden angularVelocity_14 -2.8121221517393816e-13 -6.602669370130138e-13 7.596694116649606e-13
  translation -0.8482402003156416 0.05160788541525659 0.8183769269814576
  rotation 0.003504022962772468 -0.9999933114742918 0.001048250808057493 0.5813636961938872
  controller "anaglyph"
  bodySlot [
    DEF SC_MAIN_ELEMENT HingeJoint {
      jointParameters HingeJointParameters {
        position -7.35748439950612e-09
        anchor 0 0.2 0.05
        minStop -0.5
        maxStop 0.5
      }
      device [
        RotationalMotor {
          name "sc_main_element"
          minPosition -0.5
          maxPosition 0.5
        }
      ]
      endPoint Solid {
        translation 0 0.2 0.05
        rotation 1 0 0 0
        children [
          Shape {
            appearance PBRAppearance {
              roughness 1
              metalness 0
            }
            geometry Box {
              size 0.1 0.025 0.025
            }
          }
          DEF SC_RIGHT_HINGE_JOINT HingeJoint {
            jointParameters HingeJointParameters {
              position 0.015998634876343454
              axis 0 1 0
              anchor 0.02 0 -0.0125
            }
            device [
              RotationalMotor {
                name "sc_right_motor"
                maxPosition 0.7
              }
            ]
            endPoint Solid {
              translation 0.02 0 -0.0125
              rotation 0 1 0 0.015998634876345293
              children [
                DEF SC_RIGHT_CAMERA Camera {
                  name "sc_right_camera"
                  width 256
                  height 128
                }
                Shape {
                  appearance PBRAppearance {
                    baseColor 0 1 1
                    roughness 1
                    metalness 0
                  }
                  geometry Sphere {
                    radius 0.01
                  }
                }
              ]
            }
          }
          DEF SC_LEFT_HINGE_JOINT HingeJoint {
            jointParameters HingeJointParameters {
              position -0.015998634876343454
              axis 0 1 0
              anchor -0.02 0 -0.0125
            }
            device [
              RotationalMotor {
                name "sc_left_motor"
                minPosition -0.7
              }
            ]
            endPoint Solid {
              translation -0.02 0 -0.0125
              rotation 0 -1 0 0.015998634876345293
              children [
                DEF SC_LEFT_CAMERA Camera {
                  name "sc_left_camera"
                  width 256
                  height 128
                  antiAliasing TRUE
                }
                Shape {
                  appearance PBRAppearance {
                    baseColor 1 0 0
                    roughness 1
                    metalness 0
                  }
                  geometry Sphere {
                    radius 0.01
                  }
                }
              ]
              name "solid(1)"
            }
          }
          DistanceSensor {
            translation 0 0 -0.0125
            rotation 0 1 0 1.5708
            name "sc_distance_sensor"
            lookupTable [
              0 0 0
              1000 1000 0
            ]
          }
          Display {
            name "sc_display"
            width 256
            height 128
          }
        ]
        boundingObject Transform {
          translation 0 0 -0.0075
          children [
            Box {
              size 0.1 0.025 0.04
            }
          ]
        }
        physics Physics {
        }
        linearVelocity -2.1899297507817103e-12 -3.318234575999667e-14 -8.644079796528106e-14
        angularVelocity -2.824831392346933e-13 -6.596664088089021e-13 7.599918726405304e-13
      }
    }
    Transform {
      translation 0 0.1 0.05
      children [
        Shape {
          appearance PBRAppearance {
            baseColor 0.419608 0.419608 0.419608
            roughness 1
            metalness 0
          }
          geometry Cylinder {
            height 0.2
            radius 0.01
          }
        }
      ]
    }
  ]
}
