#VRML_SIM R2021a utf8
WorldInfo {
  coordinateSystem "NUE"
  contactProperties [
    ContactProperties {
      material1 "passive_wheel"
      coulombFriction [
        0
      ]
    }
  ]
}
Viewpoint {
  orientation -0.09509272012662762 -0.9640604290504899 -0.24808237284801996 2.647760896817514
  position -25.852173619819883 26.653902681472832 -45.17115407594776
}
TexturedBackground {
}
TexturedBackgroundLight {
}
DEF GROUND Solid {
  children [
    DEF GROUND_SHAPE Group {
      children [
        Transform {
          translation -8 0 -8
          children [
            Shape {
              appearance Grass {
                type "mossy"
                textureTransform TextureTransform {
                  scale 8.5 8.5
                }
              }
              geometry ElevationGrid {
                height [
                  0, 0, 0, 0, 0, 0, 0, 0, 0, 0, 0, 0, 0, 0, 0, 0, 0, 0, 0.0734148, 0.277421, 0.254337, 0.270417, 0.174982, 0.171189, 0.2473, 0.240992, 0.152361, 0.110575, 0.0978332, 0.126226, 0.106899, 0.0670659, 0.00953075, 0, 0, 0.499106, 0.798685, 0.613379, 0.322475, 0.287311, 0.266366, 0.418124, 0.525612, 0.451978, 0.30729, 0.0753625, 0.0480358, 0.0532171, 0.0870809, 0.0265759, 0, 0, 0.862448, 1.07618, 0.821001, 0.384595, 0.210389, 0.0983306, 0.331182, 0.347343, 0.263181, 0.13356, 0.0145599, 0.0762221, 0.100532, 0.243507, 0.159553, 0, 0, 0.75534, 0.984221, 0.864925, 0.447235, 0.0751634, 0.0222157, 0.078995, 0.102868, 0.0300013, 0.0114454, 0.00744961, 0.00984787, 0.204083, 0.520919, 0.461261, 0, 0, 0.362822, 0.603904, 0.566029, 0.340368, 0.102151, 0.0404528, 0.0668038, 0.00744951, 0.00933689, 0.0504858, 0.00744961, -0.000948593, 0.113054, 0.320988, 0.289012, 0, 0, 0.24704, 0.327251, 0.277966, 0.170757, 0.0771545, 0.0929641, 0.00744947, 0.00744951, 0.00744954, 0.00744958, 0.00744961, 0.0223858, 0.0165338, 0.0943175, 0.0460902, 0, 0, 0.205381, 0.266736, 0.119044, 0.124862, 0.0668763, 0.106241, 0.00744947, 0.00744951, 0.00744954, 0.00744958, 0.00744961, 0.00747269, 0.0113116, 0.0207513, 0.0670393, 0, 0, 0.131618, 0.109085, 0.0721561, 0.169558, 0.124192, 0.00986459, 0.00744947, 0.00744951, 0.00744954, 0.031045, 0.0443939, 0.00800915, 0.0184385, 0.0427789, 0.204962, 0, 0, 0.283209, 0.135281, 0.068453, 0.212608, 0.159615, 0.0361041, 0.00744947, 0.00744951, 0.0121282, 0.145762, 0.2493, 0.0458433, 0.0131252, 0.131277, 0.19891, 0, 0, 0.660028, 0.539195, 0.111397, 0.132591, 0.105425, 0.0289037, 0.00744947, 0.00744951, 0.00930376, 0.162809, 0.219176, 0.0290093, 0.0131459, 0.0436956, 0.0856175, 0, 0, 0.577927, 0.513154, 0.0907302, 0.0479889, 0.0704255, 0.019278, 0.00747491, 0.00932149, 0.0307641, 0.178685, 0.171126, 0.00346421, 0.0308989, 0.0948634, 0.262075, 0, 0, 0.315194, 0.205858, 0.0314991, 0.0365704, 0.127151, 0.142281, 0.00631048, 0.0559231, 0.196945, 0.333009, 0.17502, 0.00950381, 0.0639322, 0.243806, 0.282763, 0, 0, 0.233297, 0.177544, 0.0450179, 0.0682162, 0.129357, 0.0562887, 0.0190858, 0.120147, 0.389857, 0.381918, 0.0861915, -0.000387524, 0.178523, 0.482041, 0.357671, 0, 0, 0.00946765, 0.0925988, 0.208856, 0.242312, 0.359189, 0.320955, 0.189391, 0.194184, 0.352838, 0.288278, 0.142815, 0.143518, 0.27195, 0.517513, 0.504371, 0, 0, 0.037447, 0.126832, 0.314132, 0.26641, 0.227191, 0.16272, 0.107686, 0.12869, 0.0911368, 0.130659, 0.0368771, 0.108887, 0.0914181, 0.249301, 0.291638, 0, 0, 0, 0, 0, 0, 0, 0, 0, 0, 0, 0, 0, 0, 0, 0, 0, 0
                ]
                xDimension 17
                zDimension 17
              }
            }
          ]
        }
        Shape {
          appearance Grass {
            type "mossy"
            textureTransform TextureTransform {
              scale 250 250
            }
          }
          geometry Plane {
            size 500 500
          }
        }
      ]
    }
  ]
  boundingObject USE GROUND_SHAPE
}
Rock10cm {
  translation -1.02326 0 -0.866326
}
Oak {
  translation 0 0 3
}
SimpleTree {
  translation 8 0 8
  name "tree(1)"
}
SimpleTree {
  translation -8 0 8
  name "tree(3)"
}
SimpleTree {
  translation 8 0 -8
  name "tree(2)"
}
SimpleTree {
  translation -8 0 -8
  name "tree(4)"
}
E-puck {
  hidden position_0_0 2671.2104227713444
  hidden position_0_1 2825.894044846192
  hidden linearVelocity_0 1.4132522500117281e-06 -2.8141404110707906e-09 1.335804455967112e-06
  hidden angularVelocity_0 -1.0398953774003186e-06 -1.8793570967793537e-06 -1.125739923545556e-06
  hidden rotation_1 1 0 0 5.426518087159456
  hidden linearVelocity_1 1.4195925798094336e-06 -3.1836901464690435e-08 1.379898207297271e-06
  hidden angularVelocity_1 2.6803153135164424 -0.006597040959045518 -0.024895789447652174
  hidden rotation_2 0.9999999999999999 0 0 1.5393433846217413
  hidden linearVelocity_2 1.4175981390102539e-06 2.538003136514762e-08 1.280662374648911e-06
  hidden angularVelocity_2 2.941510455172313 -0.007239755065803598 -0.027321835514217147
  translation -1.2094337796052028 0.00793566402751488 -0.0155523835800709
  rotation 0.0012188023748399813 0.9999962040220243 -0.002471125717855001 -3.132298948963537
}
Wheelbarrow {
  translation -3 0 5
}
Gnome {
}
Rock17cm {
  translation 5 -0.037219 -8
  rotation 0 -1 0 4.61434
  name "rock 17 cm(1)"
}
Rock17cm {
  translation 5 -0.037219 8
  rotation 0 -1 0 4.61434
  name "rock 17 cm(6)"
}
Rock17cm {
  translation 0 0 -8
  name "rock 17 cm(2)"
}
Rock17cm {
  translation 0 0 8
  name "rock 17 cm(5)"
}
Rock17cm {
  translation -5 0 -8
  rotation 0 -1 0 3.40996
  name "rock 17 cm(3)"
}
Rock17cm {
  translation -5 0 8
  rotation 0 -1 0 3.40996
  name "rock 17 cm(7)"
}
Rock17cm {
  translation 8 0 0
}
Rock17cm {
  translation -8 0 0
  name "rock 17 cm(4)"
}
Create {
  hidden position_0_1 1.0845421003904993e-07
  hidden position_0_2 1.13596121984166e-06
  hidden rotation_8 -1 0 0 1.0745380149674385e-07
  hidden rotation_9 -1 0 0 1.1360119910565718e-06
  hidden translation_13 1.1810932543099284e-07 -7.467245091556662e-05 2.0503017950090907e-08
  hidden rotation_13 5.382974466373104e-12 1 6.790619136135273e-12 0.7269320000000291
  hidden translation_14 1.1851391168438141e-07 -7.467247698305507e-05 1.9418999519515978e-08
  hidden rotation_14 -5.612406186017332e-12 1 8.295677831960116e-12 -0.7269300000000273
  translation -1.0020293598218972 0.05325303862433484 1.0019529691224647
  rotation -0.012077941741228917 -0.9995593377822641 -0.02711555965819545 0.5702060567948776
  controller "anaglyph"
  bodySlot [
    DEF SC_MAIN_ELEMENT HingeJoint {
      jointParameters HingeJointParameters {
        position -1.4562073601293413e-08
        anchor 0 0.2 0.05
        minStop -0.5
        maxStop 0.5
      }
      device [
        RotationalMotor {
          name "sc_main_element"
          minPosition -0.5
          maxPosition 0.5
        }
      ]
      endPoint Solid {
        translation 0 0.2 0.05
        rotation 1 0 0 0
        children [
          Shape {
            appearance PBRAppearance {
              roughness 1
              metalness 0
            }
            geometry Box {
              size 0.1 0.025 0.025
            }
          }
          DEF SC_RIGHT_HINGE_JOINT HingeJoint {
            jointParameters HingeJointParameters {
              position 0.015998634876343454
              axis 0 1 0
              anchor 0.02 0 -0.0125
            }
            device [
              RotationalMotor {
                name "sc_right_motor"
                maxPosition 0.7
              }
            ]
            endPoint Solid {
              translation 0.02 0 -0.0125
              rotation 0 1 0 0.015998634876345293
              children [
                DEF SC_RIGHT_CAMERA Camera {
                  name "sc_right_camera"
                  width 256
                  height 128
                }
                Shape {
                  appearance PBRAppearance {
                    baseColor 0 1 1
                    roughness 1
                    metalness 0
                  }
                  geometry Sphere {
                    radius 0.01
                  }
                }
              ]
            }
          }
          DEF SC_LEFT_HINGE_JOINT HingeJoint {
            jointParameters HingeJointParameters {
              position -0.015998634876343454
              axis 0 1 0
              anchor -0.02 0 -0.0125
            }
            device [
              RotationalMotor {
                name "sc_left_motor"
                minPosition -0.7
              }
            ]
            endPoint Solid {
              translation -0.02 0 -0.0125
              rotation 0 -1 0 0.015998634876345293
              children [
                DEF SC_LEFT_CAMERA Camera {
                  name "sc_left_camera"
                  width 256
                  height 128
                  antiAliasing TRUE
                }
                Shape {
                  appearance PBRAppearance {
                    baseColor 1 0 0
                    roughness 1
                    metalness 0
                  }
                  geometry Sphere {
                    radius 0.01
                  }
                }
              ]
              name "solid(1)"
            }
          }
          DistanceSensor {
            translation 0 0 -0.0125
            rotation 0 1 0 1.5708
            name "sc_distance_sensor"
            lookupTable [
              0 0 0
              1000 1000 0
            ]
          }
          Display {
            name "sc_display"
            width 256
            height 128
          }
        ]
        boundingObject Transform {
          translation 0 0 -0.0075
          children [
            Box {
              size 0.1 0.025 0.04
            }
          ]
        }
        physics Physics {
        }
        linearVelocity 5.122915149419369e-07 -1.0059801763162125e-06 -1.0216063573549726e-06
        angularVelocity -2.355646736693374e-06 -4.324204611997848e-06 -3.540365513154165e-07
      }
    }
    Transform {
      translation 0 0.1 0.05
      children [
        Shape {
          appearance PBRAppearance {
            baseColor 0.419608 0.419608 0.419608
            roughness 1
            metalness 0
          }
          geometry Cylinder {
            height 0.2
            radius 0.01
          }
        }
      ]
    }
  ]
}
